Workbook
Name BSCheck: Model!$F$119
Name L_Scenarios: Scenarios!$D$12:$D$14
Name million: Inp!$F$12
Name S_Scenarios: Scenarios!$E$11
Name ScenarioUSed: Scenarios!$D$11

Sheet Cover
C7: CTD Industries
C8: ="Financial Model for "&$D$14+1&" to "&$D$14+5 -> Financial Model for 2021 to 2025
C11: Modeller | D11: Animashaun Jafar
C12: Version | D12: Ver 1.01
C13: Circularity in Model | D13: Net Interest Expense Line of the P&L
C14: Base Year | D14: =Hist!I7 -> 2020

Sheet Hist
B2: CTD Industries
B3: Income Statement
B5: ($ Millions)
G7: 2018 | H7: 2019 | I7: 2020
B9: Revenue Growth | H9: =H13/G13-1 -> 0.10350333 | I9: =I13/H13-1 -> 0.086390331
B10: COGS (% of revenue) | G10: =G15/G13 -> 0.71735387 | H10: =H15/H13 -> 0.72797685 | I10: =I15/I13 -> 0.72829834
B11: SG&A (% of revenue) | G11: =G16/G13 -> 0.16261232 | H11: =H16/H13 -> 0.15453797 | I11: =I16/I13 -> 0.1496135
C13: Revenue | G13: 3194.1 | H13: 3524.7 | I13: 3829.2
C15: Cost of Sales | G15: 2291.3 | H15: 2565.9 | I15: 2788.8
C16: SG&A | G16: 519.4 | H16: 544.7 | I16: 572.9
C17: Total Costs | G17: =SUM(G15:G16) -> 2810.7 | H17: =SUM(H15:H16) -> 3110.6 | I17: =SUM(I15:I16) -> 3361.7
C19: Cost Adjustments - (Gain) / Loss | G19: -7 | H19: -4.2 | I19: 76
C20: EBITDA | G20: =G13-G17-G19 -> 390.4 | H20: =H13-H17-H19 -> 418.3 | I20: =I13-I17-I19 -> 391.5
C22: Depreciation & Amortization | G22: 95.1 | H22: 113.2 | I22: 126.2
C23: EBIT | G23: =G20-G22 -> 295.3 | H23: =H20-H22 -> 305.1 | I23: =I20-I22 -> 265.3
C25: Cost Adjustments - (Gain) / Loss | G25: 116 | H25: 123.9 | I25: 105.8
C26: Net Interest Expense | G26: 62 | H26: 56.6 | I26: 59.1
C27: EBT | G27: =G23-G25-G26 -> 117.3 | H27: =H23-H25-H26 -> 124.6 | I27: =I23-I25-I26 -> 100.4
C29: Current Taxes | G29: 40.5 | H29: 22.7 | I29: 24.8
C30: Deferred Income Taxes | G30: 16.9 | H30: 31.7 | I30: 24
C31: Total Income Taxes | G31: =SUM(G29:G30) -> 57.4 | H31: =SUM(H29:H30) -> 54.4 | I31: =SUM(I29:I30) -> 48.8
C33: Net Income | G33: =G27-G31 -> 59.9 | H33: =H27-H31 -> 70.2 | I33: =I27-I31 -> 51.6
C35: Preferred Dividend | G35: 0.544 | H35: 0.544 | I35: 0.544
C36: Net Income to Common | G36: =G33-G35 -> 59.356 | H36: =H33-H35 -> 69.656 | I36: =I33-I35 -> 51.056
B41: CTD Industries
B42: Cash Flow Statement
B44: ($ Millions)
G46: 2018 | H46: 2019 | I46: 2020
B48: Operating Activities
C49: Net Income | G49: 59.9 | H49: 70.2 | I49: 51.6
C50: Depreciation | G50: 95.1 | H50: 113.2 | I50: 126.2
C51: Deferred Income Taxes | G51: 16.9 | H51: 31.7 | I51: 24
C52: Changes in Working Capital | G52: -119 | H52: -4.5 | I52: -83.8
C53: Other | G53: 161.9 | H53: 164.2 | I53: 242.1
C54: Operating Cash Flow | G54: =SUM(G49:G53) -> 214.8 | H54: =SUM(H49:H53) -> 374.8 | I54: =SUM(I49:I53) -> 360.1
B57: Investing Activities
C58: CAPEX | G58: -134.4 | H58: -158.7 | I58: -194.1
C59: Asset Disposal | G59: 2 | H59: 3.4 | I59: 10.5
C60: Other | G60: -14.9 | H60: -11.3 | I60: -15.4
C61: Investing Cash Flow | G61: =SUM(G58:G60) -> -147.3 | H61: =SUM(H58:H60) -> -166.6 | I61: =SUM(I58:I60) -> -199
...

Sheet Summary
B2: =Cover!$C$7 -> CTD Industries | I2: ="Financial Forecast: "&L6&" to "&P6 -> Financial Forecast: 2021 to 2025
B3: Summary | I3: =IF(BSCheck=0,"BS Check: OK","BS Check: ERROR") -> BS Check: OK | K3: =ScenarioUSed -> Scenario: Worst Case
I5: Actual | J5: Actual | K5: Actual | L5: Forecast | M5: Forecast | N5: Forecast | O5: Forecast | P5: Forecast
E6: Units | F6: Trend | I6: =Hist!G7 -> 2018 | J6: =Hist!H7 -> 2019 | K6: =Hist!I7 -> 2020 | L6: =K6+1 -> 2021 | M6: =L6+1 -> 2022 | N6: =M6+1 -> 2023 | O6: =N6+1 -> 2024 | P6: =O6+1 -> 2025
B8: Analysis Based on : Base Case Scenario
C10: Revenue
D11: Gross Revenue | E11: $'m | I11: 3194.1 | J11: 3524.7 | K11: 3829.2 | L11: 4025.012 | M11: 4231.2989 | N11: 4448.6336 | O11: 4370.7679 | P11: 4480.0371
D12: Growth Rate | E12: % | J12: 0.10350333 | K12: 0.086390331 | L12: 0.051136536 | M12: 0.05125125 | N12: 0.05136359 | O12: -0.01750329 | P12: 0.025
C13: EBITDA
D14: EBITDA | E14: $'m | I14: 390.4 | J14: 418.3 | K14: 391.5 | L14: 544.1017 | M14: 658.35656 | N14: 780.68444 | O14: 669.17896 | P14: 704.41638
D15: Growth Rate | E15: % | J15: 0.071465164 | K15: -0.06406885 | L15: 0.38978724 | M15: 0.20998805 | N15: 0.18580795 | O15: -0.14283041 | P15: 0.052657691
D16: EBITA Margin | E16: % | I16: 0.12222535 | J16: 0.11867677 | K16: 0.10224068 | L16: 0.13518014 | M16: 0.15559207 | N16: 0.17548859 | O16: 0.15310329 | P16: 0.1572345
C17: Net Profit
D18: Net Profit | E18: $'m | I18: 291.9 | J18: 318 | K18: 263.2 | L18: 242.33499 | M18: 318.794 | N18: 395.32477 | O18: 307.91855 | P18: 322.95339
D19: Growth Rate | E19: % | J19: 0.089414183 | K19: -0.17232704 | L19: -0.07927434 | M19: 0.31550956 | N19: 0.2400634 | O19: -0.22109978 | P19: 0.048827325
D20: Net Profit Margin | E20: % | I20: 0.091387245 | J20: 0.090220444 | K20: 0.068734984 | L20: 0.060207272 | M20: 0.075341877 | N20: 0.088864313 | O20: 0.070449531 | P20: 0.072087213
C21: Dupont Analysis
D22: ROE | E22: % | I22: -7.0602748 | J22: -11.362012 | K22: -16.730231 | L22: 2.8306444 | M22: 0.7960422 | N22: 0.51627727 | O22: 0.29075246 | P22: 0.23794516
D23: Net Profit Margin | E23: % | I23: 0.091387245 | J23: 0.090220444 | K23: 0.068734984 | L23: 0.060207272 | M23: 0.075341877 | N23: 0.088864313 | O23: 0.070449531 | P23: 0.072087213
D24: Asset Turnover | E24: times | I24: 1.6492862 | J24: 1.203334 | K24: 1.3603963 | L24: 1.6862288 | M24: 1.6399473 | N24: 1.6011196 | O24: 1.5019726 | P24: 1.4678268
D25: Financial Leverage | E25: times | I25: -46.842492 | J25: -104.656 | K25: -178.91991 | L25: 27.88174 | M25: 6.4427277 | N25: 3.6285393 | O25: 2.7477883 | P25: 2.2487637
B27: Analysis Based on : Best Case Scenario
C29: Revenue
D30: Gross Revenue | E30: $'m | I30: 3194.1 | J30: 3524.7 | K30: 3829.2 | L30: 4100.8391 | M30: 4392.3949 | N30: 4705.3557 | O30: 4556.6786 | P30: 4719.5228
D31: Growth Rate | E31: % | J31: 0.10350333 | K31: 0.086390331 | L31: 0.070938859 | M31: 0.071096629 | N31: 0.071250599 | O31: -0.031597415 | P31: 0.035737471
C32: EBITDA
D33: EBITDA | E33: $'m | I33: 390.4 | J33: 418.3 | K33: 391.5 | L33: 626.90076 | M33: 836.46737 | N33: 1064.5477 | O33: 923.98549 | P33: 1032.3393
D34: Growth Rate | E34: % | J34: 0.071465164 | K34: -0.06406885 | L34: 0.60127908 | M34: 0.33428992 | N34: 0.27267097 | O34: -0.1320394 | P34: 0.11726783
D35: EBITA Margin | E35: % | I35: 0.12222535 | J35: 0.11867677 | K35: 0.10224068 | L35: 0.15287134 | M35: 0.19043537 | N35: 0.22624171 | O35: 0.20277609 | P35: 0.21873806
C36: Net Profit
D37: Net Profit | E37: $'m | I37: 291.9 | J37: 318 | K37: 263.2 | L37: 300.72437 | M37: 445.03993 | N37: 596.52168 | O37: 489.61766 | P37: 556.9981
D38: Growth Rate | E38: % | J38: 0.089414183 | K38: -0.17232704 | L38: 0.14256978 | M38: 0.47989317 | N38: 0.34037787 | O38: -0.17921229 | P38: 0.13761848
D39: Net Profit Margin | E39: % | I39: 0.091387245 | J39: 0.090220444 | K39: 0.068734984 | L39: 0.073332399 | M39: 0.10132056 | N39: 0.12677504 | O39: 0.10745056 | P39: 0.11802001
C40: Dupont Analysis
D41: ROE | E41: % | I41: -7.0602748 | J41: -11.362012 | K41: -16.730231 | L41: 2.3239317 | M41: 0.82575331 | N41: 0.56537195 | O41: 0.32977799 | P41: 0.28440881
D42: Net Profit Margin | E42: % | I42: 0.091387245 | J42: 0.090220444 | K42: 0.068734984 | L42: 0.073332399 | M42: 0.10132056 | N42: 0.12677504 | O42: 0.10745056 | P42: 0.11802001
D43: Asset Turnover | E43: times | I43: 1.6492862 | J43: 1.203334 | K43: 1.3603963 | L43: 1.7027742 | M43: 1.6470672 | N43: 1.5515038 | O43: 1.3897034 | P43: 1.3127772
D44: Financial Leverage | E44: times | I44: -46.842492 | J44: -104.656 | K44: -178.91991 | L44: 18.61103 | M44: 4.9481335 | N44: 2.8744029 | O44: 2.2084668 | P44: 1.8356775
B47: Analysis Based on : Worst Case Scenario
C49: Revenue
...

Sheet Inp
B2: =Cover!$C$7 -> CTD Industries | I2: ="Financial Forecast: "&L6&" to "&P6 -> Financial Forecast: 2021 to 2025
B3: Inputs & Assumptions | I3: =IF(BSCheck=0,"BS Check: OK","BS Check: ERROR") -> BS Check: OK | K3: =ScenarioUSed -> Scenario: Worst Case
I5: Actual | J5: Actual | K5: Actual | L5: Forecast | M5: Forecast | N5: Forecast | O5: Forecast | P5: Forecast
E6: Units | F6: Inputs | I6: =Hist!G7 -> 2018 | J6: =Hist!H7 -> 2019 | K6: =Hist!I7 -> 2020 | L6: =K6+1 -> 2021 | M6: =L6+1 -> 2022 | N6: =M6+1 -> 2023 | O6: =N6+1 -> 2024 | P6: =O6+1 -> 2025
B9: General Assumptions
D11: Days in the Year | I11: =DATE(I6,12,31)-DATE(I6,1,1)+1 -> 365 | J11: =DATE(J6,12,31)-DATE(J6,1,1)+1 -> 365 | K11: =DATE(K6,12,31)-DATE(K6,1,1)+1 -> 366 | L11: =DATE(L6,12,31)-DATE(L6,1,1)+1 -> 365 | M11: =DATE(M6,12,31)-DATE(M6,1,1)+1 -> 365 | N11: =DATE(N6,12,31)-DATE(N6,1,1)+1 -> 365 | O11: =DATE(O6,12,31)-DATE(O6,1,1)+1 -> 366 | P11: =DATE(P6,12,31)-DATE(P6,1,1)+1 -> 365
D12: Millions | E12: Constant | F12: 1000000
C14: Style Guide
D16: Number | E16: Number | F16: 1234.5
D17: Input | E17: Number
D18: Percent | E18: Percent | F18: 0.23
D19: Multiples | E19: Number | F19: 12.5
D20: Linked Cell | E20: Number
D21: Units | E21: Text | F21: Text
D22: Headings 1 | E22: Text | F22: TEXT
D23: Headings 2 | E23: Text | F23: Text
D24: Headings 3 | E24: Text | F24: Text
B26: Revenue Assumptions
C28: Core Revenue Assumptions
D30: Total Sales | E30: $'m | K30: =Hist!I13 -> 3829.2 | L30: ="<<"&_xlfn.FORMULATEXT(K30) -> <<=Hist!I13
D31: Auxillary Sales | E31: $'m | K31: 574.5
D32: Industrial Monitor Sales | E32: $'m | K32: =K30-K31 -> 3254.7 | L32: ="<<"&_xlfn.FORMULATEXT(K32) -> <<=K30-K31
D33: Average Unit Sales Price | E33: $ | K33: 14105
D34: Quantity of Industrial Monitors Sold | E34: units | K34: =K32*million/K33 -> 230747.96 | L34: ="<<"&_xlfn.FORMULATEXT(K34) -> <<=K32*million/K33
D35: Volume capacity | E35: units | L35: 260000 | M35: 260000 | N35: 260000 | O35: 240000 | P35: 240000
D37: Increase in Average Sales Price per Device | E37: % | K37: =_xlfn.FORMULATEXT(L37)&" >>" -> =Scenarios!L33 >> | L37: =Scenarios!L33 -> 0.01 | M37: =Scenarios!M33 -> 0.01 | N37: =Scenarios!N33 -> 0.01 | O37: =Scenarios!O33 -> 0.01 | P37: =Scenarios!P33 -> 0.01
D38: Volume Growth Rate in Devices | E38: units | K38: =_xlfn.FORMULATEXT(L38)&" >>" -> =Scenarios!L19 >> | L38: =Scenarios!L19 -> 0.02 | M38: =Scenarios!M19 -> 0.02 | N38: =Scenarios!N19 -> 0.02 | O38: =Scenarios!O19 -> 0.02 | P38: =Scenarios!P19 -> 0.02
D39: =Scenarios!B24 -> Auxiliary Business YoY Sales Growth | E39: % | K39: =_xlfn.FORMULATEXT(L39)&" >>" -> =Scenarios!L26 >> | L39: =Scenarios!L26 -> 0.01 | M39: =Scenarios!M26 -> 0.01 | N39: =Scenarios!N26 -> 0.01 | O39: =Scenarios!O26 -> 0.01 | P39: =Scenarios!P26 -> 0.01
D41: Additional Devices | E41: units | K41: =K34 -> 230747.96 | L41: =K41*(1+L38) -> 235362.92 | M41: =L41*(1+M38) -> 240070.18 | N41: =M41*(1+N38) -> 244871.58 | O41: =N41*(1+O38) -> 249769.01 | P41: =O41*(1+P38) -> 254764.39
B43: Production Cost Assumptions
D45: Cost of Sales | E45: $'m | K45: =Hist!I15 -> 2788.8 | L45: ="<<"&_xlfn.FORMULATEXT(K45) -> <<=Hist!I15
D46: Variable Cost | E46: $'m | K46: 0.25
D47: Fixed Cost | E47: $'m | K47: =1-K46 -> 0.75 | L47: ="<<"&_xlfn.FORMULATEXT(K47) -> <<=1-K46
D48: Variable cost per Device | E48: $ | K48: =K45*K46*million/K34 -> 3021.4785 | L48: ="<<"&_xlfn.FORMULATEXT(K48) -> <<=K45*K46*million/K34
D49: Fixed Cost | E49: $'m | K49: =K45*K47 -> 2091.6 | L49: ="<<"&_xlfn.FORMULATEXT(K49) -> <<=K45*K47
D51: SG& A | E51: $'m | L51: 615
D53: Cost inflation | E53: % | K53: =_xlfn.FORMULATEXT(L53)&" >>" -> =Scenarios!L40 >> | L53: =Scenarios!L40 -> 0.03 | M53: =Scenarios!M40 -> 0.03 | N53: =Scenarios!N40 -> 0.03 | O53: =Scenarios!O40 -> 0.03 | P53: =Scenarios!P40 -> 0.03
B56: Capex & Depreciation Assumptions
C58: Capex (Tangible Assets)
D59: Additions | E59: $'m | L59: 225 | M59: 250 | N59: 275 | O59: 275 | P59: 275
...

Sheet Scenarios
B2: =Cover!$C$7 -> CTD Industries | I2: ="Financial Forecast: "&L6&" to "&P6 -> Financial Forecast: 2021 to 2025
B3: Scenario Analysis | I3: =IF(BSCheck=0,"BS Check: OK","BS Check: ERROR") -> BS Check: OK | K3: =ScenarioUSed -> Scenario: Worst Case
I5: Actual | J5: Actual | K5: Actual | L5: Forecast | M5: Forecast | N5: Forecast | O5: Forecast | P5: Forecast
E6: Units | F6: Inputs | I6: =Hist!G7 -> 2018 | J6: =Hist!H7 -> 2019 | K6: =Hist!I7 -> 2020 | L6: =K6+1 -> 2021 | M6: =L6+1 -> 2022 | N6: =M6+1 -> 2023 | O6: =N6+1 -> 2024 | P6: =O6+1 -> 2025
B9: Scenario Used
D11: ="Scenario: "&INDEX(L_Scenarios,S_Scenarios) -> Scenario: Worst Case | E11: 3
D12: Base Case
D13: Best Case
D14: Worst Case
B17: Core Business: Volume Growth
D19: Used in the Model | E19: Units | L19: =INDEX(L20:L22,S_Scenarios) -> 0.02 | M19: =INDEX(M20:M22,S_Scenarios) -> 0.02 | N19: =INDEX(N20:N22,S_Scenarios) -> 0.02 | O19: =INDEX(O20:O22,S_Scenarios) -> 0.02 | P19: =INDEX(P20:P22,S_Scenarios) -> 0.02
D20: =D$12 -> Base Case | E20: Units | L20: 0.03 | M20: 0.03 | N20: 0.03 | O20: 0.03 | P20: 0.03
D21: =D$13 -> Best Case | E21: Units | L21: 0.04 | M21: 0.04 | N21: 0.04 | O21: 0.04 | P21: 0.04
D22: =D$14 -> Worst Case | E22: Units | L22: 0.02 | M22: 0.02 | N22: 0.02 | O22: 0.02 | P22: 0.02
B24: Auxiliary Business YoY Sales Growth
D26: Used in the Model | E26: Units | L26: =INDEX(L27:L29,S_Scenarios) -> 0.01 | M26: =INDEX(M27:M29,S_Scenarios) -> 0.01 | N26: =INDEX(N27:N29,S_Scenarios) -> 0.01 | O26: =INDEX(O27:O29,S_Scenarios) -> 0.01 | P26: =INDEX(P27:P29,S_Scenarios) -> 0.01
D27: =D$12 -> Base Case | E27: Units | L27: 0.025 | M27: 0.025 | N27: 0.025 | O27: 0.025 | P27: 0.025
D28: =D$13 -> Best Case | E28: Units | L28: 0.04 | M28: 0.04 | N28: 0.04 | O28: 0.04 | P28: 0.04
D29: =D$14 -> Worst Case | E29: Units | L29: 0.01 | M29: 0.01 | N29: 0.01 | O29: 0.01 | P29: 0.01
B31: Core Business: Sales Price Inflation Scenarios
D33: Used in the Model | E33: % | L33: =INDEX(L34:L36,S_Scenarios) -> 0.01 | M33: =INDEX(M34:M36,S_Scenarios) -> 0.01 | N33: =INDEX(N34:N36,S_Scenarios) -> 0.01 | O33: =INDEX(O34:O36,S_Scenarios) -> 0.01 | P33: =INDEX(P34:P36,S_Scenarios) -> 0.01
D34: Base Case | E34: % | L34: 0.025 | M34: 0.025 | N34: 0.025 | O34: 0.025 | P34: 0.025
D35: Best Case | E35: % | L35: 0.035 | M35: 0.035 | N35: 0.035 | O35: 0.035 | P35: 0.035
D36: Worst Case | E36: % | L36: 0.01 | M36: 0.01 | N36: 0.01 | O36: 0.01 | P36: 0.01
B38: Cost Inflation Scenario
D40: Used in the Model | E40: % | L40: =INDEX(L41:L43,S_Scenarios) -> 0.03 | M40: =INDEX(M41:M43,S_Scenarios) -> 0.03 | N40: =INDEX(N41:N43,S_Scenarios) -> 0.03 | O40: =INDEX(O41:O43,S_Scenarios) -> 0.03 | P40: =INDEX(P41:P43,S_Scenarios) -> 0.03
D41: Base Case | E41: % | L41: 0.02 | M41: 0.02 | N41: 0.02 | O41: 0.02 | P41: 0.02
D42: Best Case | E42: % | L42: 0.015 | M42: 0.015 | N42: 0.015 | O42: 0.015 | P42: 0.015
D43: Worst Case | E43: % | L43: 0.03 | M43: 0.03 | N43: 0.03 | O43: 0.03 | P43: 0.03

Sheet Model
B2: =Cover!$C$7 -> CTD Industries | I2: ="Financial Forecast: "&L6&" to "&P6 -> Financial Forecast: 2021 to 2025
B3: Model & Schedules | I3: =IF(BSCheck=0,"BS Check: OK","BS Check: ERROR") -> BS Check: OK | K3: =ScenarioUSed -> Scenario: Worst Case
I5: Actual | J5: Actual | K5: Actual | L5: Forecast | M5: Forecast | N5: Forecast | O5: Forecast | P5: Forecast | Q5: Formula in
E6: Units | F6: Inputs | I6: =Hist!G7 -> 2018 | J6: =Hist!H7 -> 2019 | K6: =Hist!I7 -> 2020 | L6: =K6+1 -> 2021 | M6: =L6+1 -> 2022 | N6: =M6+1 -> 2023 | O6: =N6+1 -> 2024 | P6: =O6+1 -> 2025 | Q6: =L6 -> 2021
A8: FINANCIAL STATEMENTS
B10: Income Statement
D12: =Hist!C13 -> Revenue | E12: $'m | I12: =Hist!G13 -> 3194.1 | J12: =Hist!H13 -> 3524.7 | K12: =Hist!I13 -> 3829.2 | L12: =L143 -> 3933.2369 | M12: =M143 -> 4040.2997 | N12: =N143 -> 4150.4786 | O12: =O143 -> 4120.4797 | P12: =P143 -> 4161.6845 | Q12: =_xlfn.FORMULATEXT(L12) -> =L143
D14: =Hist!C15 -> Cost of Sales | E14: $'m | I14: =Hist!G15 -> 2291.3 | J14: =Hist!H15 -> 2565.9 | K14: =Hist!I15 -> 2788.8 | L14: =L160 -> 2886.8263 | M14: =M160 -> 2988.5202 | N14: =N160 -> 3094.0283 | O14: =O160 -> 3170.2824 | P14: =P160 -> 3265.3909 | Q14: =_xlfn.FORMULATEXT(L14) -> =L160
D15: =Hist!C16 -> SG&A | E15: $'m | I15: =Hist!G16 -> 519.4 | J15: =Hist!H16 -> 544.7 | K15: =Hist!I16 -> 572.9 | L15: =L162 -> 615 | M15: =M162 -> 633.45 | N15: =N162 -> 652.4535 | O15: =O162 -> 672.02711 | P15: =P162 -> 692.18792 | Q15: =_xlfn.FORMULATEXT(L15) -> =L162
D16: =Hist!C17 -> Total Costs | E16: $'m | I16: =SUM(I14:I15) -> 2810.7 | J16: =SUM(J14:J15) -> 3110.6 | K16: =SUM(K14:K15) -> 3361.7 | L16: =SUM(L14:L15) -> 3501.8263 | M16: =SUM(M14:M15) -> 3621.9702 | N16: =SUM(N14:N15) -> 3746.4818 | O16: =SUM(O14:O15) -> 3842.3095 | P16: =SUM(P14:P15) -> 3957.5788 | Q16: =_xlfn.FORMULATEXT(L16) -> =SUM(L14:L15)
D18: =Hist!C19 -> Cost Adjustments - (Gain) / Loss | E18: $'m | I18: =Hist!G19 -> -7 | J18: =Hist!H19 -> -4.2 | K18: =Hist!I19 -> 76 | L18: =Inp!L137 -> 0 | M18: =Inp!M137 -> 0 | N18: =Inp!N137 -> 0 | O18: =Inp!O137 -> 0 | P18: =Inp!P137 -> 0 | Q18: =_xlfn.FORMULATEXT(L18) -> =Inp!L137
D19: =Hist!C20 -> EBITDA | E19: $'m | I19: =I12-I16-I18 -> 390.4 | J19: =J12-J16-J18 -> 418.3 | K19: =K12-K16-K18 -> 391.5 | L19: =L12-L16+L18 -> 431.41062 | M19: =M12-M16+M18 -> 418.32958 | N19: =N12-N16+N18 -> 403.99681 | O19: =O12-O16+O18 -> 278.17021 | P19: =P12-P16+P18 -> 204.10572 | Q19: =_xlfn.FORMULATEXT(L19) -> =L12-L16+L18
D21: =Hist!C22 -> Depreciation & Amortization | E21: $'m | I21: =Hist!G22 -> 95.1 | J21: =Hist!H22 -> 113.2 | K21: =Hist!I22 -> 126.2 | L21: =L200 -> 121.81333 | M21: =M200 -> 141.64667 | N21: =N200 -> 163.14667 | O21: =O200 -> 185.48 | P21: =P200 -> 207.81333 | Q21: =_xlfn.FORMULATEXT(L21) -> =L200
D22: =Hist!C23 -> EBIT | E22: $'m | I22: =I19-I21 -> 295.3 | J22: =J19-J21 -> 305.1 | K22: =K19-K21 -> 265.3 | L22: =L19-L21 -> 309.59729 | M22: =M19-M21 -> 276.68292 | N22: =N19-N21 -> 240.85015 | O22: =O19-O21 -> 92.690212 | P22: =P19-P21 -> -3.7076095 | Q22: =_xlfn.FORMULATEXT(L22) -> =L19-L21
D24: =Hist!C25 -> Cost Adjustments - (Gain) / Loss | E24: $'m | I24: =Hist!G25 -> 116 | J24: =Hist!H25 -> 123.9 | K24: =Hist!I25 -> 105.8 | L24: =Inp!L138 -> 0 | M24: =Inp!M138 -> 0 | N24: =Inp!N138 -> 0 | O24: =Inp!O138 -> 0 | P24: =Inp!P138 -> 0 | Q24: =_xlfn.FORMULATEXT(L24) -> =Inp!L138
D25: =Hist!C26 -> Net Interest Expense | E25: $'m | I25: =Hist!G26 -> 62 | J25: =Hist!H26 -> 56.6 | K25: =Hist!I26 -> 59.1 | L25: =L342 -> 59.579945 | M25: =M342 -> 48.306353 | N25: =N342 -> 47.647661 | O25: =O342 -> 49.250115 | P25: =P342 -> 53.724456 | Q25: =_xlfn.FORMULATEXT(L25) -> =L342
D26: =Hist!C27 -> EBT | E26: $'m | I26: =I22+I24-I25 -> 349.3 | J26: =J22+J24-J25 -> 372.4 | K26: =K22+K24-K25 -> 312 | L26: =L22+L24-L25 -> 250.01734 | M26: =M22+M24-M25 -> 228.37656 | N26: =N22+N24-N25 -> 193.20249 | O26: =O22+O24-O25 -> 43.440096 | P26: =P22+P24-P25 -> -57.432066 | Q26: =_xlfn.FORMULATEXT(L26) -> =L22+L24-L25
D28: =Hist!C29 -> Current Taxes | E28: $'m | I28: =Hist!G29 -> 40.5 | J28: =Hist!H29 -> 22.7 | K28: =Hist!I29 -> 24.8 | L28: =L228 -> 81.005203 | M28: =M228 -> 74.512969 | N28: =N228 -> 63.960746 | O28: =O228 -> 19.032029 | P28: =P228 -> -11.22962 | Q28: =_xlfn.FORMULATEXT(L28) -> =L228
D29: =Hist!C30 -> Deferred Income Taxes | E29: $'m | I29: =Hist!G30 -> 16.9 | J29: =Hist!H30 -> 31.7 | K29: =Hist!I30 -> 24 | L29: =-L229 -> -6 | M29: =-M229 -> -6 | N29: =-N229 -> -6 | O29: =-O229 -> -6 | P29: =-P229 -> -6 | Q29: =_xlfn.FORMULATEXT(L29) -> =-L229
D30: =Hist!C31 -> Total Income Taxes | E30: $'m | I30: =SUM(I28:I29) -> 57.4 | J30: =SUM(J28:J29) -> 54.4 | K30: =SUM(K28:K29) -> 48.8 | L30: =SUM(L28:L29) -> 75.005203 | M30: =SUM(M28:M29) -> 68.512969 | N30: =SUM(N28:N29) -> 57.960746 | O30: =SUM(O28:O29) -> 13.032029 | P30: =SUM(P28:P29) -> -17.22962 | Q30: =_xlfn.FORMULATEXT(L30) -> =SUM(L28:L29)
D32: =Hist!C33 -> Net Income | E32: $'m | I32: =I26-I30 -> 291.9 | J32: =J26-J30 -> 318 | K32: =K26-K30 -> 263.2 | L32: =L26-L30 -> 175.01214 | M32: =M26-M30 -> 159.86359 | N32: =N26-N30 -> 135.24174 | O32: =O26-O30 -> 30.408067 | P32: =P26-P30 -> -40.202446 | Q32: =_xlfn.FORMULATEXT(L32) -> =L26-L30
D34: Preferred Dividends | E34: $'m | I34: =Hist!G35 -> 0.544 | J34: =Hist!H35 -> 0.544 | K34: =Hist!I35 -> 0.544 | L34: =L279 -> 0.544 | M34: =M279 -> 5.644 | N34: =N279 -> 14.994 | O34: =O279 -> 23.494 | P34: =P279 -> 31.994 | Q34: =_xlfn.FORMULATEXT(L34) -> =L279
D35: Net Income to Common | E35: $'m | I35: =I32-I34 -> 291.356 | J35: =J32-J34 -> 317.456 | K35: =K32-K34 -> 262.656 | L35: =L32-L34 -> 174.46814 | M35: =M32-M34 -> 154.21959 | N35: =N32-N34 -> 120.24774 | O35: =O32-O34 -> 6.9140672 | P35: =P32-P34 -> -72.196446 | Q35: =_xlfn.FORMULATEXT(L35) -> =L32-L34
D37: EBITA Margin | E37: $'m | I37: =I19/I12 -> 0.12222535 | J37: =J19/J12 -> 0.11867677 | K37: =K19/K12 -> 0.10224068 | L37: =L19/L12 -> 0.10968335 | M37: =M19/M12 -> 0.10353924 | N37: =N19/N12 -> 0.097337403 | O37: =O19/O12 -> 0.067509181 | P37: =P19/P12 -> 0.049044017 | Q37: =_xlfn.FORMULATEXT(L37) -> =L19/L12
C38: Dupont Analysis
D39: ROE | E39: $'m | I39: =I32/I115 -> -7.0602748 | J39: =J32/J115 -> -11.362012 | K39: =K32/K115 -> -16.730231 | L39: =L32/L115 -> 5.0027618 | M39: =M32/M115 -> 0.69737317 | N39: =N32/N115 -> 0.34180084 | O39: =O32/O115 -> 0.06401885 | P39: =P32/P115 -> -0.083271133 | Q39: =_xlfn.FORMULATEXT(L39) -> =L32/L115
D40: Net Profit Margin | E40: $'m | I40: =I32/I12 -> 0.091387245 | J40: =J32/J12 -> 0.090220444 | K40: =K32/K12 -> 0.068734984 | L40: =L32/L12 -> 0.044495702 | M40: =M32/M12 -> 0.039567261 | N40: =N32/N12 -> 0.032584613 | O40: =O32/O12 -> 0.0073797396 | P40: =P32/P12 -> -0.0096601378 | Q40: =_xlfn.FORMULATEXT(L40) -> =L32/L12
D41: Asset Turnover | E41: $'m | I41: =I12/I95 -> 1.6492862 | J41: =J12/J95 -> 1.203334 | K41: =K12/K95 -> 1.3603963 | L41: =L12/L95 -> 1.6604926 | M41: =M12/M95 -> 1.5787388 | N41: =N12/N95 -> 1.5068242 | O41: =O12/O95 -> 1.4184588 | P41: =P12/P95 -> 1.3643265 | Q41: =_xlfn.FORMULATEXT(L41) -> =L12/L95
D42: Financial Leverage | E42: $'m | I42: =I95/I115 -> -46.842492 | J42: =J95/J115 -> -104.656 | K42: =K95/K115 -> -178.91991 | L42: =L95/L115 -> 67.710314 | M42: =M95/M115 -> 11.163978 | N42: =N95/N115 -> 6.9614221 | O42: =O95/O115 -> 6.1157553 | P42: =P95/P115 -> 6.3181922 | Q42: =_xlfn.FORMULATEXT(L42) -> =L95/L115
B45: Cash Flow Statement
C47: =Hist!B48 -> Operating Activities
D48: =Hist!C49 -> Net Income | E48: $'m | I48: =Hist!G49 -> 59.9 | J48: =Hist!H49 -> 70.2 | K48: =Hist!I49 -> 51.6 | L48: =L32 -> 175.01214 | M48: =M32 -> 159.86359 | N48: =N32 -> 135.24174 | O48: =O32 -> 30.408067 | P48: =P32 -> -40.202446 | Q48: =_xlfn.FORMULATEXT(L48) -> =L32
D49: =Hist!C50 -> Depreciation | E49: $'m | I49: =Hist!G50 -> 95.1 | J49: =Hist!H50 -> 113.2 | K49: =Hist!I50 -> 126.2 | L49: =L21 -> 121.81333 | M49: =M21 -> 141.64667 | N49: =N21 -> 163.14667 | O49: =O21 -> 185.48 | P49: =P21 -> 207.81333 | Q49: =_xlfn.FORMULATEXT(L49) -> =L21
D50: =Hist!C51 -> Deferred Income Taxes | E50: $'m | I50: =Hist!G51 -> 16.9 | J50: =Hist!H51 -> 31.7 | K50: =Hist!I51 -> 24 | L50: =L29 -> -6 | M50: =M29 -> -6 | N50: =N29 -> -6 | O50: =O29 -> -6 | P50: =P29 -> -6 | Q50: =_xlfn.FORMULATEXT(L50) -> =L29
D51: =Hist!C52 -> Changes in Working Capital | E51: $'m | I51: =Hist!G52 -> -119 | J51: =Hist!H52 -> -4.5 | K51: =Hist!I52 -> -83.8 | L51: =L252 -> -3.9549074 | M51: =M252 -> -2.6349748 | N51: =N252 -> -2.6610987 | O51: =O252 -> 7.3344463 | P51: =P252 -> 1.9007807 | Q51: =_xlfn.FORMULATEXT(L51) -> =L252
D52: Goodwiill Addition/(Impairement) | E52: $'m | L52: =-Inp!L140 -> 0 | M52: =-Inp!M140 -> 0 | N52: =-Inp!N140 -> 0 | O52: =-Inp!O140 -> 0 | P52: =-Inp!P140 -> 0 | Q52: =_xlfn.FORMULATEXT(L52) -> =-Inp!L140
D53: =Hist!C53 -> Other | E53: $'m | I53: =Hist!G53 -> 161.9 | J53: =Hist!H53 -> 164.2 | K53: =Hist!I53 -> 242.1 | L53: =-Inp!L142 -> 0 | M53: =-Inp!M142 -> 0 | N53: =-Inp!N142 -> 0 | O53: =-Inp!O142 -> 0 | P53: =-Inp!P142 -> 0 | Q53: =_xlfn.FORMULATEXT(L53) -> =-Inp!L142
D54: =Hist!C54 -> Operating Cash Flow | E54: $'m | I54: =SUM(I48:I53) -> 214.8 | J54: =SUM(J48:J53) -> 374.8 | K54: =SUM(K48:K53) -> 360.1 | L54: =SUM(L48:L53) -> 286.87057 | M54: =SUM(M48:M53) -> 292.87529 | N54: =SUM(N48:N53) -> 289.72731 | O54: =SUM(O48:O53) -> 217.22251 | P54: =SUM(P48:P53) -> 163.51167 | Q54: =_xlfn.FORMULATEXT(L54) -> =SUM(L48:L53)
C56: =Hist!B57 -> Investing Activities
D57: =Hist!C58 -> CAPEX | E57: $'m | I57: =Hist!G58 -> -134.4 | J57: =Hist!H58 -> -158.7 | K57: =Hist!I58 -> -194.1 | L57: =-L167 -> -225 | M57: =-M167 -> -250 | N57: =-N167 -> -275 | O57: =-O167 -> -275 | P57: =-P167 -> -275 | Q57: =_xlfn.FORMULATEXT(L57) -> =-L167
...
